Workbook

Sheet License authorities
A1: # | B1: Emirate | C1: Licensing authority (dropdown text) | D1: Short name | E1: Type | F1: Can serve customers in Dubai homes? | G1: Notes
A2: 1 | B2: Abu Dhabi | C2: Abu Dhabi Department of Economic Development | D2: ADDED | E2: Mainland | F2: Yes (mainland) | G2: Mainland licenses in Abu Dhabi, Al Ain and Al Dhafra
A3: 2 | B3: Abu Dhabi | C3: Abu Dhabi Global Market | D3: ADGM | E3: Financial free zone | F3: Check | G3: Financial free zone, Al Maryah Island
A4: 3 | B4: Abu Dhabi | C4: Khalifa Economic Zones Abu Dhabi | D4: KEZAD | E4: Free zone | F4: Check | G4: Includes Khalifa Industrial Zone and former ZonesCorp areas
A5: 4 | B5: Abu Dhabi | C5: Masdar City Free Zone | D5: Masdar | E5: Free zone | F5: Check
A6: 5 | B6: Abu Dhabi | C6: twofour54 (Abu Dhabi media zone) | D6: twofour54 | E6: Free zone | F6: Check | G6: Media and entertainment
A7: 6 | B7: Abu Dhabi | C7: Abu Dhabi Airports Free Zone | D7: ADAFZ | E7: Free zone | F7: Check
A8: 7 | B8: Dubai | C8: Dubai Department of Economy and Tourism (formerly DED) | D8: DET | E8: Mainland | F8: Yes (mainland) | G8: Mainland licenses in Dubai
A9: 8 | B9: Dubai | C9: Dubai Multi Commodities Centre | D9: DMCC | E9: Free zone | F9: Check | G9: Jumeirah Lakes Towers
A10: 9 | B10: Dubai | C10: Jebel Ali Free Zone | D10: JAFZA | E10: Free zone | F10: Check
A11: 10 | B11: Dubai | C11: Dubai Airport Freezone | D11: DAFZ | E11: Free zone | F11: Check | G11: Part of Dubai Integrated Economic Zones (DIEZ)
A12: 11 | B12: Dubai | C12: Dubai Silicon Oasis | D12: DSO | E12: Free zone | F12: Check | G12: Part of DIEZ
A13: 12 | B13: Dubai | C13: Dubai CommerCity | D13: DCC | E13: Free zone | F13: Check | G13: Part of DIEZ
A14: 13 | B14: Dubai | C14: International Free Zone Authority | D14: IFZA | E14: Free zone | F14: Check | G14: Based in Dubai Silicon Oasis
A15: 14 | B15: Dubai | C15: Meydan Free Zone | D15: Meydan FZ | E15: Free zone | F15: Check
A16: 15 | B16: Dubai | C16: Dubai South Free Zone | D16: Dubai South | E16: Free zone | F16: Check | G16: Includes Dubai World Central
A17: 16 | B17: Dubai | C17: Dubai World Trade Centre Free Zone | D17: DWTC | E17: Free zone | F17: Check
A18: 17 | B18: Dubai | C18: Dubai International Financial Centre | D18: DIFC | E18: Financial free zone | F18: Check | G18: Financial free zone
A19: 18 | B19: Dubai | C19: Dubai Healthcare City Authority | D19: DHCC | E19: Free zone | F19: Check
A20: 19 | B20: Dubai | C20: Dubai Development Authority (TECOM free zones) | D20: DDA | E20: Free zone | F20: Check | G20: Dubai Internet City, Media City, Knowledge Park, Studio City, Production City, Outsource City, Science Park, Design District (d3) and others
A21: 20 | B21: Dubai | C21: Dubai Maritime City | D21: DMC | E21: Free zone | F21: Check
A22: 21 | B22: Dubai | C22: International Humanitarian City | D22: IHC | E22: Free zone | F22: Check | G22: Humanitarian organisations only
A23: 22 | B23: Dubai | C23: Expo City Dubai Free Zone | D23: Expo City | E23: Free zone | F23: Check
A24: 23 | B24: Dubai | C24: Jebel Ali Free Zone Offshore | D24: JAFZA Offshore | E24: Offshore | F24: No | G24: Offshore company — cannot trade inside UAE
A25: 24 | B25: Sharjah | C25: Sharjah Economic Development Department | D25: SEDD | E25: Mainland | F25: Yes (mainland) | G25: Mainland licenses in Sharjah, incl. Khor Fakkan and Kalba
A26: 25 | B26: Sharjah | C26: Sharjah Airport International Free Zone | D26: SAIF Zone | E26: Free zone | F26: Check
A27: 26 | B27: Sharjah | C27: Hamriyah Free Zone | D27: HFZA | E27: Free zone | F27: Check
A28: 27 | B28: Sharjah | C28: Sharjah Media City | D28: Shams | E28: Free zone | F28: Check
A29: 28 | B29: Sharjah | C29: Sharjah Publishing City Free Zone | D29: SPC | E29: Free zone | F29: Check
A30: 29 | B30: Sharjah | C30: Sharjah Research, Technology and Innovation Park | D30: SRTIP | E30: Free zone | F30: Check
A31: 30 | B31: Sharjah | C31: Sharjah Healthcare City | D31: SHCC | E31: Free zone | F31: Check
A32: 31 | B32: Ajman | C32: Ajman Department of Economic Development | D32: Ajman DED | E32: Mainland | F32: Yes (mainland) | G32: Mainland licenses in Ajman
A33: 32 | B33: Ajman | C33: Ajman Free Zone | D33: AFZ | E33: Free zone | F33: Check
A34: 33 | B34: Ajman | C34: Ajman Media City Free Zone | D34: AMC | E34: Free zone | F34: Check
A35: 34 | B35: Ajman | C35: Ajman NuVentures Centre Free Zone | D35: ANCFZ | E35: Free zone | F35: Check
A36: 35 | B36: Umm Al Quwain | C36: Umm Al Quwain Department of Economic Development | D36: UAQ DED | E36: Mainland | F36: Yes (mainland) | G36: Mainland licenses in Umm Al Quwain
A37: 36 | B37: Umm Al Quwain | C37: Umm Al Quwain Free Trade Zone | D37: UAQ FTZ | E37: Free zone | F37: Check
A38: 37 | B38: Ras Al Khaimah | C38: Ras Al Khaimah Department of Economic Development | D38: RAK DED | E38: Mainland | F38: Yes (mainland) | G38: Mainland licenses in Ras Al Khaimah
A39: 38 | B39: Ras Al Khaimah | C39: Ras Al Khaimah Economic Zone | D39: RAKEZ | E39: Free zone | F39: Check
A40: 39 | B40: Ras Al Khaimah | C40: RAK Digital Assets Oasis | D40: RAK DAO | E40: Free zone | F40: Check | G40: Digital / virtual asset companies
...

Sheet Summary
A1: Emirate | B1: Mainland | C1: Free zone | D1: Financial free zone | E1: Offshore | F1: Total
A2: Abu Dhabi | B2: =COUNTIFS('License authorities'!$B:$B,$A2,'License authorities'!$E:$E,B$1) -> 1 | C2: =COUNTIFS('License authorities'!$B:$B,$A2,'License authorities'!$E:$E,C$1) -> 4 | D2: =COUNTIFS('License authorities'!$B:$B,$A2,'License authorities'!$E:$E,D$1) -> 1 | E2: =COUNTIFS('License authorities'!$B:$B,$A2,'License authorities'!$E:$E,E$1) -> 0 | F2: =SUM(B2:E2) -> 6
A3: Dubai | B3: =COUNTIFS('License authorities'!$B:$B,$A3,'License authorities'!$E:$E,B$1) -> 1 | C3: =COUNTIFS('License authorities'!$B:$B,$A3,'License authorities'!$E:$E,C$1) -> 14 | D3: =COUNTIFS('License authorities'!$B:$B,$A3,'License authorities'!$E:$E,D$1) -> 1 | E3: =COUNTIFS('License authorities'!$B:$B,$A3,'License authorities'!$E:$E,E$1) -> 1 | F3: =SUM(B3:E3) -> 17
A4: Sharjah | B4: =COUNTIFS('License authorities'!$B:$B,$A4,'License authorities'!$E:$E,B$1) -> 1 | C4: =COUNTIFS('License authorities'!$B:$B,$A4,'License authorities'!$E:$E,C$1) -> 6 | D4: =COUNTIFS('License authorities'!$B:$B,$A4,'License authorities'!$E:$E,D$1) -> 0 | E4: =COUNTIFS('License authorities'!$B:$B,$A4,'License authorities'!$E:$E,E$1) -> 0 | F4: =SUM(B4:E4) -> 7
A5: Ajman | B5: =COUNTIFS('License authorities'!$B:$B,$A5,'License authorities'!$E:$E,B$1) -> 1 | C5: =COUNTIFS('License authorities'!$B:$B,$A5,'License authorities'!$E:$E,C$1) -> 3 | D5: =COUNTIFS('License authorities'!$B:$B,$A5,'License authorities'!$E:$E,D$1) -> 0 | E5: =COUNTIFS('License authorities'!$B:$B,$A5,'License authorities'!$E:$E,E$1) -> 0 | F5: =SUM(B5:E5) -> 4
A6: Umm Al Quwain | B6: =COUNTIFS('License authorities'!$B:$B,$A6,'License authorities'!$E:$E,B$1) -> 1 | C6: =COUNTIFS('License authorities'!$B:$B,$A6,'License authorities'!$E:$E,C$1) -> 1 | D6: =COUNTIFS('License authorities'!$B:$B,$A6,'License authorities'!$E:$E,D$1) -> 0 | E6: =COUNTIFS('License authorities'!$B:$B,$A6,'License authorities'!$E:$E,E$1) -> 0 | F6: =SUM(B6:E6) -> 2
A7: Ras Al Khaimah | B7: =COUNTIFS('License authorities'!$B:$B,$A7,'License authorities'!$E:$E,B$1) -> 1 | C7: =COUNTIFS('License authorities'!$B:$B,$A7,'License authorities'!$E:$E,C$1) -> 3 | D7: =COUNTIFS('License authorities'!$B:$B,$A7,'License authorities'!$E:$E,D$1) -> 0 | E7: =COUNTIFS('License authorities'!$B:$B,$A7,'License authorities'!$E:$E,E$1) -> 1 | F7: =SUM(B7:E7) -> 5
A8: Fujairah | B8: =COUNTIFS('License authorities'!$B:$B,$A8,'License authorities'!$E:$E,B$1) -> 1 | C8: =COUNTIFS('License authorities'!$B:$B,$A8,'License authorities'!$E:$E,C$1) -> 2 | D8: =COUNTIFS('License authorities'!$B:$B,$A8,'License authorities'!$E:$E,D$1) -> 0 | E8: =COUNTIFS('License authorities'!$B:$B,$A8,'License authorities'!$E:$E,E$1) -> 0 | F8: =SUM(B8:E8) -> 3
A9: Total | B9: =SUM(B2:B8) -> 7 | C9: =SUM(C2:C8) -> 33 | D9: =SUM(D2:D8) -> 2 | E9: =SUM(E2:E8) -> 2 | F9: =SUM(F2:F8) -> 44

Sheet Read me
A1: How to use
A2: • Column C is the text to show in the "Trade license issued by" dropdown, grouped by Emirate.
A3: • "Other" is a fallback: show a text box so the supplier can type the authority.
A4: • Mainland licenses can work anywhere in the UAE mainland. Free zone and offshore licenses usually need extra permits to serve customers outside their zone — HourX should check these during approval ("Check" in column F).
A6: Important
A7: • This list was put together from general knowledge (up to mid-2026). It could not be checked online in this session.
A8: • Free zones merge and rename from time to time (e.g. KEZAD, DIEZ). Please confirm the list with each authority's official website or your PRO before the dev team uses it.
